Workbook

Sheet Dashboard
A2: IT Cost, Subscription and Renewal Dashboard
A3: Report Month | B3: 46266 | D3: Fiscal Year Start | E3: =DATE(YEAR(B3)-(MONTH(B3)<4),4,1) -> 46113 | G3: Monthly IT Budget | H3: 0
A5: Cost overview | F5: Renewals and control exceptions
A6: Annual IT run-rate | B6: =B7+B8 -> 0 | F6: Active software applications | G6: =COUNTIF('Software Register'!$Y$7:$Y$206,"Active") -> 0
A7: Software support run-rate | B7: =SUMIFS('Software Register'!$Q$7:$Q$206,'Software Register'!$Y$7:$Y$206,"Active") -> 0 | F7: Active online subscriptions | G7: =COUNTIF('Online Subscriptions'!$AD$7:$AD$206,"Active") -> 0
A8: Online subscriptions run-rate | B8: =SUMIFS('Online Subscriptions'!$S$7:$S$206,'Online Subscriptions'!$AD$7:$AD$206,"Active") -> 0 | F8: Renewals due within 30 days | G8: =COUNTIF('Software Register'!$AA$7:$AA$206,"Due within 30 days")+COUNTIF('Online Subscriptions'!$AF$7:$AF$206,"Due within 30 days") -> 0
A9: AI subscriptions run-rate | B9: =SUMIFS('Online Subscriptions'!$S$7:$S$206,'Online Subscriptions'!$AD$7:$AD$206,"Active",'Online Subscriptions'!$C$7:$C$206,"AI") -> 0 | F9: Renewals due in 31-60 days | G9: =COUNTIF('Software Register'!$AA$7:$AA$206,"Due in 31-60 days")+COUNTIF('Online Subscriptions'!$AF$7:$AF$206,"Due in 31-60 days") -> 0
A10: Current month actual spend | B10: =SUMIFS('IT Spend Log'!$K$7:$K$306,'IT Spend Log'!$B$7:$B$306,$B$3) -> 0 | F10: Expired items | G10: =COUNTIF('Software Register'!$AA$7:$AA$206,"Expired")+COUNTIF('Online Subscriptions'!$AF$7:$AF$206,"Expired") -> 0
A11: Current month budget | B11: =$H$3 -> 0 | F11: Low utilization subscriptions (<50%) | G11: =COUNTIFS('Online Subscriptions'!$AD$7:$AD$206,"Active",'Online Subscriptions'!$M$7:$M$206,"<0.5",'Online Subscriptions'!$M$7:$M$206,">=0") -> 0
A12: Current month variance | B12: =B10-B11 -> 0 | F12: Security review pending | G12: =COUNTIF('Online Subscriptions'!$AB$7:$AB$206,"Pending") -> 0
A13: FYTD actual spend | B13: =SUMIFS('IT Spend Log'!$K$7:$K$306,'IT Spend Log'!$A$7:$A$306,">="&$E$3,'IT Spend Log'!$A$7:$A$306,"<"&DATE(YEAR($B$3),MONTH($B$3)+1,1)) -> 0 | F13: Auto-renew subscriptions | G13: =COUNTIFS('Online Subscriptions'!$AD$7:$AD$206,"Active",'Online Subscriptions'!$V$7:$V$206,"Yes") -> 0
A16: Subscription cost by type | E16: Spend by department (FYTD)
A17: Subscription Type | B17: Active Tools | C17: Annualized Cost (INR) | E17: Department | F17: Transactions | G17: Actual Spend (INR)
A18: AI | B18: =COUNTIFS('Online Subscriptions'!$C$7:$C$206,A18,'Online Subscriptions'!$AD$7:$AD$206,"Active") -> 0 | C18: =SUMIFS('Online Subscriptions'!$S$7:$S$206,'Online Subscriptions'!$C$7:$C$206,A18,'Online Subscriptions'!$AD$7:$AD$206,"Active") -> 0 | E18: Accounts & Finance | F18: =COUNTIFS('IT Spend Log'!$H$7:$H$306,E18,'IT Spend Log'!$A$7:$A$306,">="&$E$3,'IT Spend Log'!$A$7:$A$306,"<"&DATE(YEAR($B$3),MONTH($B$3)+1,1)) -> 0 | G18: =SUMIFS('IT Spend Log'!$K$7:$K$306,'IT Spend Log'!$H$7:$H$306,E18,'IT Spend Log'!$A$7:$A$306,">="&$E$3,'IT Spend Log'!$A$7:$A$306,"<"&DATE(YEAR($B$3),MONTH($B$3)+1,1)) -> 0
A19: SaaS | B19: =COUNTIFS('Online Subscriptions'!$C$7:$C$206,A19,'Online Subscriptions'!$AD$7:$AD$206,"Active") -> 0 | C19: =SUMIFS('Online Subscriptions'!$S$7:$S$206,'Online Subscriptions'!$C$7:$C$206,A19,'Online Subscriptions'!$AD$7:$AD$206,"Active") -> 0 | E19: Retail | F19: =COUNTIFS('IT Spend Log'!$H$7:$H$306,E19,'IT Spend Log'!$A$7:$A$306,">="&$E$3,'IT Spend Log'!$A$7:$A$306,"<"&DATE(YEAR($B$3),MONTH($B$3)+1,1)) -> 0 | G19: =SUMIFS('IT Spend Log'!$K$7:$K$306,'IT Spend Log'!$H$7:$H$306,E19,'IT Spend Log'!$A$7:$A$306,">="&$E$3,'IT Spend Log'!$A$7:$A$306,"<"&DATE(YEAR($B$3),MONTH($B$3)+1,1)) -> 0
A20: Cloud Hosting | B20: =COUNTIFS('Online Subscriptions'!$C$7:$C$206,A20,'Online Subscriptions'!$AD$7:$AD$206,"Active") -> 0 | C20: =SUMIFS('Online Subscriptions'!$S$7:$S$206,'Online Subscriptions'!$C$7:$C$206,A20,'Online Subscriptions'!$AD$7:$AD$206,"Active") -> 0 | E20: E-commerce | F20: =COUNTIFS('IT Spend Log'!$H$7:$H$306,E20,'IT Spend Log'!$A$7:$A$306,">="&$E$3,'IT Spend Log'!$A$7:$A$306,"<"&DATE(YEAR($B$3),MONTH($B$3)+1,1)) -> 0 | G20: =SUMIFS('IT Spend Log'!$K$7:$K$306,'IT Spend Log'!$H$7:$H$306,E20,'IT Spend Log'!$A$7:$A$306,">="&$E$3,'IT Spend Log'!$A$7:$A$306,"<"&DATE(YEAR($B$3),MONTH($B$3)+1,1)) -> 0
A21: Data / Analytics | B21: =COUNTIFS('Online Subscriptions'!$C$7:$C$206,A21,'Online Subscriptions'!$AD$7:$AD$206,"Active") -> 0 | C21: =SUMIFS('Online Subscriptions'!$S$7:$S$206,'Online Subscriptions'!$C$7:$C$206,A21,'Online Subscriptions'!$AD$7:$AD$206,"Active") -> 0 | E21: Production | F21: =COUNTIFS('IT Spend Log'!$H$7:$H$306,E21,'IT Spend Log'!$A$7:$A$306,">="&$E$3,'IT Spend Log'!$A$7:$A$306,"<"&DATE(YEAR($B$3),MONTH($B$3)+1,1)) -> 0 | G21: =SUMIFS('IT Spend Log'!$K$7:$K$306,'IT Spend Log'!$H$7:$H$306,E21,'IT Spend Log'!$A$7:$A$306,">="&$E$3,'IT Spend Log'!$A$7:$A$306,"<"&DATE(YEAR($B$3),MONTH($B$3)+1,1)) -> 0
A22: Communication | B22: =COUNTIFS('Online Subscriptions'!$C$7:$C$206,A22,'Online Subscriptions'!$AD$7:$AD$206,"Active") -> 0 | C22: =SUMIFS('Online Subscriptions'!$S$7:$S$206,'Online Subscriptions'!$C$7:$C$206,A22,'Online Subscriptions'!$AD$7:$AD$206,"Active") -> 0 | E22: Warehouse | F22: =COUNTIFS('IT Spend Log'!$H$7:$H$306,E22,'IT Spend Log'!$A$7:$A$306,">="&$E$3,'IT Spend Log'!$A$7:$A$306,"<"&DATE(YEAR($B$3),MONTH($B$3)+1,1)) -> 0 | G22: =SUMIFS('IT Spend Log'!$K$7:$K$306,'IT Spend Log'!$H$7:$H$306,E22,'IT Spend Log'!$A$7:$A$306,">="&$E$3,'IT Spend Log'!$A$7:$A$306,"<"&DATE(YEAR($B$3),MONTH($B$3)+1,1)) -> 0
A23: Domain / Website | B23: =COUNTIFS('Online Subscriptions'!$C$7:$C$206,A23,'Online Subscriptions'!$AD$7:$AD$206,"Active") -> 0 | C23: =SUMIFS('Online Subscriptions'!$S$7:$S$206,'Online Subscriptions'!$C$7:$C$206,A23,'Online Subscriptions'!$AD$7:$AD$206,"Active") -> 0 | E23: HR | F23: =COUNTIFS('IT Spend Log'!$H$7:$H$306,E23,'IT Spend Log'!$A$7:$A$306,">="&$E$3,'IT Spend Log'!$A$7:$A$306,"<"&DATE(YEAR($B$3),MONTH($B$3)+1,1)) -> 0 | G23: =SUMIFS('IT Spend Log'!$K$7:$K$306,'IT Spend Log'!$H$7:$H$306,E23,'IT Spend Log'!$A$7:$A$306,">="&$E$3,'IT Spend Log'!$A$7:$A$306,"<"&DATE(YEAR($B$3),MONTH($B$3)+1,1)) -> 0
A24: Marketing | B24: =COUNTIFS('Online Subscriptions'!$C$7:$C$206,A24,'Online Subscriptions'!$AD$7:$AD$206,"Active") -> 0 | C24: =SUMIFS('Online Subscriptions'!$S$7:$S$206,'Online Subscriptions'!$C$7:$C$206,A24,'Online Subscriptions'!$AD$7:$AD$206,"Active") -> 0 | E24: Marketing | F24: =COUNTIFS('IT Spend Log'!$H$7:$H$306,E24,'IT Spend Log'!$A$7:$A$306,">="&$E$3,'IT Spend Log'!$A$7:$A$306,"<"&DATE(YEAR($B$3),MONTH($B$3)+1,1)) -> 0 | G24: =SUMIFS('IT Spend Log'!$K$7:$K$306,'IT Spend Log'!$H$7:$H$306,E24,'IT Spend Log'!$A$7:$A$306,">="&$E$3,'IT Spend Log'!$A$7:$A$306,"<"&DATE(YEAR($B$3),MONTH($B$3)+1,1)) -> 0
A25: Security | B25: =COUNTIFS('Online Subscriptions'!$C$7:$C$206,A25,'Online Subscriptions'!$AD$7:$AD$206,"Active") -> 0 | C25: =SUMIFS('Online Subscriptions'!$S$7:$S$206,'Online Subscriptions'!$C$7:$C$206,A25,'Online Subscriptions'!$AD$7:$AD$206,"Active") -> 0 | E25: Management | F25: =COUNTIFS('IT Spend Log'!$H$7:$H$306,E25,'IT Spend Log'!$A$7:$A$306,">="&$E$3,'IT Spend Log'!$A$7:$A$306,"<"&DATE(YEAR($B$3),MONTH($B$3)+1,1)) -> 0 | G25: =SUMIFS('IT Spend Log'!$K$7:$K$306,'IT Spend Log'!$H$7:$H$306,E25,'IT Spend Log'!$A$7:$A$306,">="&$E$3,'IT Spend Log'!$A$7:$A$306,"<"&DATE(YEAR($B$3),MONTH($B$3)+1,1)) -> 0
A26: Other | B26: =COUNTIFS('Online Subscriptions'!$C$7:$C$206,A26,'Online Subscriptions'!$AD$7:$AD$206,"Active") -> 0 | C26: =SUMIFS('Online Subscriptions'!$S$7:$S$206,'Online Subscriptions'!$C$7:$C$206,A26,'Online Subscriptions'!$AD$7:$AD$206,"Active") -> 0 | E26: IT | F26: =COUNTIFS('IT Spend Log'!$H$7:$H$306,E26,'IT Spend Log'!$A$7:$A$306,">="&$E$3,'IT Spend Log'!$A$7:$A$306,"<"&DATE(YEAR($B$3),MONTH($B$3)+1,1)) -> 0 | G26: =SUMIFS('IT Spend Log'!$K$7:$K$306,'IT Spend Log'!$H$7:$H$306,E26,'IT Spend Log'!$A$7:$A$306,">="&$E$3,'IT Spend Log'!$A$7:$A$306,"<"&DATE(YEAR($B$3),MONTH($B$3)+1,1)) -> 0
A29: Monthly budget versus actual
A30: Month | B30: Budget (INR) | C30: Actual (INR) | D30: Variance (INR) | N30: Month | O30: Budget (INR) | P30: Actual (INR)
A31: =$E$3 -> 46113 | B31: =IF(A31<=$B$3,$H$3,0) -> 0 | C31: =SUMIFS('IT Spend Log'!$K$7:$K$306,'IT Spend Log'!$B$7:$B$306,A31) -> 0 | D31: =C31-B31 -> 0 | N31: =TEXT(A31,"mmm-yy") -> Apr-26 | O31: =B31 -> 0 | P31: =C31 -> 0
A32: =DATE(YEAR(A31),MONTH(A31)+1,1) -> 46143 | B32: =IF(A32<=$B$3,$H$3,0) -> 0 | C32: =SUMIFS('IT Spend Log'!$K$7:$K$306,'IT Spend Log'!$B$7:$B$306,A32) -> 0 | D32: =C32-B32 -> 0 | N32: =TEXT(A32,"mmm-yy") -> May-26 | O32: =B32 -> 0 | P32: =C32 -> 0
A33: =DATE(YEAR(A32),MONTH(A32)+1,1) -> 46174 | B33: =IF(A33<=$B$3,$H$3,0) -> 0 | C33: =SUMIFS('IT Spend Log'!$K$7:$K$306,'IT Spend Log'!$B$7:$B$306,A33) -> 0 | D33: =C33-B33 -> 0 | N33: =TEXT(A33,"mmm-yy") -> Jun-26 | O33: =B33 -> 0 | P33: =C33 -> 0
A34: =DATE(YEAR(A33),MONTH(A33)+1,1) -> 46204 | B34: =IF(A34<=$B$3,$H$3,0) -> 0 | C34: =SUMIFS('IT Spend Log'!$K$7:$K$306,'IT Spend Log'!$B$7:$B$306,A34) -> 0 | D34: =C34-B34 -> 0 | N34: =TEXT(A34,"mmm-yy") -> Jul-26 | O34: =B34 -> 0 | P34: =C34 -> 0
A35: =DATE(YEAR(A34),MONTH(A34)+1,1) -> 46235 | B35: =IF(A35<=$B$3,$H$3,0) -> 0 | C35: =SUMIFS('IT Spend Log'!$K$7:$K$306,'IT Spend Log'!$B$7:$B$306,A35) -> 0 | D35: =C35-B35 -> 0 | N35: =TEXT(A35,"mmm-yy") -> Aug-26 | O35: =B35 -> 0 | P35: =C35 -> 0
A36: =DATE(YEAR(A35),MONTH(A35)+1,1) -> 46266 | B36: =IF(A36<=$B$3,$H$3,0) -> 0 | C36: =SUMIFS('IT Spend Log'!$K$7:$K$306,'IT Spend Log'!$B$7:$B$306,A36) -> 0 | D36: =C36-B36 -> 0 | N36: =TEXT(A36,"mmm-yy") -> Sep-26 | O36: =B36 -> 0 | P36: =C36 -> 0
A37: =DATE(YEAR(A36),MONTH(A36)+1,1) -> 46296 | B37: =IF(A37<=$B$3,$H$3,0) -> 0 | C37: =SUMIFS('IT Spend Log'!$K$7:$K$306,'IT Spend Log'!$B$7:$B$306,A37) -> 0 | D37: =C37-B37 -> 0 | N37: =TEXT(A37,"mmm-yy") -> Oct-26 | O37: =B37 -> 0 | P37: =C37 -> 0
A38: =DATE(YEAR(A37),MONTH(A37)+1,1) -> 46327 | B38: =IF(A38<=$B$3,$H$3,0) -> 0 | C38: =SUMIFS('IT Spend Log'!$K$7:$K$306,'IT Spend Log'!$B$7:$B$306,A38) -> 0 | D38: =C38-B38 -> 0 | N38: =TEXT(A38,"mmm-yy") -> Nov-26 | O38: =B38 -> 0 | P38: =C38 -> 0
A39: =DATE(YEAR(A38),MONTH(A38)+1,1) -> 46357 | B39: =IF(A39<=$B$3,$H$3,0) -> 0 | C39: =SUMIFS('IT Spend Log'!$K$7:$K$306,'IT Spend Log'!$B$7:$B$306,A39) -> 0 | D39: =C39-B39 -> 0 | N39: =TEXT(A39,"mmm-yy") -> Dec-26 | O39: =B39 -> 0 | P39: =C39 -> 0
A40: =DATE(YEAR(A39),MONTH(A39)+1,1) -> 46388 | B40: =IF(A40<=$B$3,$H$3,0) -> 0 | C40: =SUMIFS('IT Spend Log'!$K$7:$K$306,'IT Spend Log'!$B$7:$B$306,A40) -> 0 | D40: =C40-B40 -> 0 | N40: =TEXT(A40,"mmm-yy") -> Jan-27 | O40: =B40 -> 0 | P40: =C40 -> 0
A41: =DATE(YEAR(A40),MONTH(A40)+1,1) -> 46419 | B41: =IF(A41<=$B$3,$H$3,0) -> 0 | C41: =SUMIFS('IT Spend Log'!$K$7:$K$306,'IT Spend Log'!$B$7:$B$306,A41) -> 0 | D41: =C41-B41 -> 0 | N41: =TEXT(A41,"mmm-yy") -> Feb-27 | O41: =B41 -> 0 | P41: =C41 -> 0
A42: =DATE(YEAR(A41),MONTH(A41)+1,1) -> 46447 | B42: =IF(A42<=$B$3,$H$3,0) -> 0 | C42: =SUMIFS('IT Spend Log'!$K$7:$K$306,'IT Spend Log'!$B$7:$B$306,A42) -> 0 | D42: =C42-B42 -> 0 | N42: =TEXT(A42,"mmm-yy") -> Mar-27 | O42: =B42 -> 0 | P42: =C42 -> 0
A45: Monthly reporting actions
A46: 1 | B46: Update the software and subscription registers | C46: Confirm owners, users, costs, renewal dates, status and control fields
A47: 2 | B47: Record invoices and payments | C47: Enter expense date, base amount, GST, TDS, budget and payment status in IT Spend Log
A48: 3 | B48: Review exceptions | C48: Close expired renewals, low utilization, pending security reviews and duplicate tools
...

Sheet Software Register
A2: IT Software Register
A3: Update the blue input cells. Formula-driven fields and dashboard results update automatically.
A6: Record ID | B6: Software / Application | C6: Category | D6: Deployment | E6: Purpose / Module | F6: Vendor | G6: Business Owner | H6: IT Owner | I6: Department | J6: License Type | K6: Purchased Licenses | L6: Assigned Licenses | M6: Utilization % | N6: Version / Plan | O6: Start Date | P6: Renewal / Support Due | Q6: Annual Support Cost (INR) | R6: Payment Frequency | S6: Auto-Renew | T6: Criticality | U6: Data Sensitivity | V6: SSO / MFA | W6: Contract / PO No. | X6: Invoice No. | Y6: Status | Z6: Days to Renewal | AA6: Renewal Flag | AB6: Risk / Issue | AC6: Action Required | AD6: Remarks
M7: =IF(OR(K7="",K7=0,L7=""),"",L7/K7) | Z7: =IF(P7="","",P7-TODAY()) | AA7: =IF(P7="","",IF(Y7<>"Active","Inactive",IF(Z7<0,"Expired",IF(Z7<=30,"Due within 30 days",IF(Z7<=60,"Due in 31-60 days",IF(Z7<=90,"Due in 61-90 days","Later"))))))
M8: =IF(OR(K8="",K8=0,L8=""),"",L8/K8) | Z8: =IF(P8="","",P8-TODAY()) | AA8: =IF(P8="","",IF(Y8<>"Active","Inactive",IF(Z8<0,"Expired",IF(Z8<=30,"Due within 30 days",IF(Z8<=60,"Due in 31-60 days",IF(Z8<=90,"Due in 61-90 days","Later"))))))
M9: =IF(OR(K9="",K9=0,L9=""),"",L9/K9) | Z9: =IF(P9="","",P9-TODAY()) | AA9: =IF(P9="","",IF(Y9<>"Active","Inactive",IF(Z9<0,"Expired",IF(Z9<=30,"Due within 30 days",IF(Z9<=60,"Due in 31-60 days",IF(Z9<=90,"Due in 61-90 days","Later"))))))
M10: =IF(OR(K10="",K10=0,L10=""),"",L10/K10) | Z10: =IF(P10="","",P10-TODAY()) | AA10: =IF(P10="","",IF(Y10<>"Active","Inactive",IF(Z10<0,"Expired",IF(Z10<=30,"Due within 30 days",IF(Z10<=60,"Due in 31-60 days",IF(Z10<=90,"Due in 61-90 days","Later"))))))
M11: =IF(OR(K11="",K11=0,L11=""),"",L11/K11) | Z11: =IF(P11="","",P11-TODAY()) | AA11: =IF(P11="","",IF(Y11<>"Active","Inactive",IF(Z11<0,"Expired",IF(Z11<=30,"Due within 30 days",IF(Z11<=60,"Due in 31-60 days",IF(Z11<=90,"Due in 61-90 days","Later"))))))
M12: =IF(OR(K12="",K12=0,L12=""),"",L12/K12) | Z12: =IF(P12="","",P12-TODAY()) | AA12: =IF(P12="","",IF(Y12<>"Active","Inactive",IF(Z12<0,"Expired",IF(Z12<=30,"Due within 30 days",IF(Z12<=60,"Due in 31-60 days",IF(Z12<=90,"Due in 61-90 days","Later"))))))
M13: =IF(OR(K13="",K13=0,L13=""),"",L13/K13) | Z13: =IF(P13="","",P13-TODAY()) | AA13: =IF(P13="","",IF(Y13<>"Active","Inactive",IF(Z13<0,"Expired",IF(Z13<=30,"Due within 30 days",IF(Z13<=60,"Due in 31-60 days",IF(Z13<=90,"Due in 61-90 days","Later"))))))
M14: =IF(OR(K14="",K14=0,L14=""),"",L14/K14) | Z14: =IF(P14="","",P14-TODAY()) | AA14: =IF(P14="","",IF(Y14<>"Active","Inactive",IF(Z14<0,"Expired",IF(Z14<=30,"Due within 30 days",IF(Z14<=60,"Due in 31-60 days",IF(Z14<=90,"Due in 61-90 days","Later"))))))
M15: =IF(OR(K15="",K15=0,L15=""),"",L15/K15) | Z15: =IF(P15="","",P15-TODAY()) | AA15: =IF(P15="","",IF(Y15<>"Active","Inactive",IF(Z15<0,"Expired",IF(Z15<=30,"Due within 30 days",IF(Z15<=60,"Due in 31-60 days",IF(Z15<=90,"Due in 61-90 days","Later"))))))
M16: =IF(OR(K16="",K16=0,L16=""),"",L16/K16) | Z16: =IF(P16="","",P16-TODAY()) | AA16: =IF(P16="","",IF(Y16<>"Active","Inactive",IF(Z16<0,"Expired",IF(Z16<=30,"Due within 30 days",IF(Z16<=60,"Due in 31-60 days",IF(Z16<=90,"Due in 61-90 days","Later"))))))
M17: =IF(OR(K17="",K17=0,L17=""),"",L17/K17) | Z17: =IF(P17="","",P17-TODAY()) | AA17: =IF(P17="","",IF(Y17<>"Active","Inactive",IF(Z17<0,"Expired",IF(Z17<=30,"Due within 30 days",IF(Z17<=60,"Due in 31-60 days",IF(Z17<=90,"Due in 61-90 days","Later"))))))
M18: =IF(OR(K18="",K18=0,L18=""),"",L18/K18) | Z18: =IF(P18="","",P18-TODAY()) | AA18: =IF(P18="","",IF(Y18<>"Active","Inactive",IF(Z18<0,"Expired",IF(Z18<=30,"Due within 30 days",IF(Z18<=60,"Due in 31-60 days",IF(Z18<=90,"Due in 61-90 days","Later"))))))
... M206: =IF(OR(K206="",K206=0,L206=""),"",L206/K206) | Z206: =IF(P206="","",P206-TODAY()) | AA206: =IF(P206="","",IF(Y206<>"Active","Inactive",IF(Z206<0,"Expired",IF(Z206<=30,"Due within 30 days",IF(Z206<=60,"Due in 31-60 days",IF(Z206<=90,"Due in 61-90 days","Later"))))))

Sheet Online Subscriptions
A2: AI and Online Subscription Register
A3: Update the blue input cells. Formula-driven fields and dashboard results update automatically.
A6: Subscription ID | B6: Tool / Platform | C6: Subscription Type | D6: Use Case | E6: Vendor | F6: Website | G6: Business Owner | H6: Admin Account / Email | I6: Department | J6: Plan | K6: Seats | L6: Active Users | M6: Utilization % | N6: Billing Currency | O6: Billing Amount | P6: FX Rate to INR | Q6: Billing Amount (INR) | R6: Billing Frequency | S6: Annualized Cost (INR) | T6: Start Date | U6: Renewal Date | V6: Auto-Renew | W6: Payment Mode | X6: Card / Bank Last 4 | Y6: GST / Tax Credit | Z6: Data Shared | AA6: AI Data Retention / Training | AB6: Security Review | AC6: Criticality | AD6: Status | AE6: Days to Renewal | AF6: Renewal Flag | AG6: Duplicate / Overlap | AH6: Cost Saving Action | AI6: Remarks
M7: =IF(OR(K7="",K7=0,L7=""),"",L7/K7) | Q7: =IF(OR(O7="",P7=""),"",O7*P7) | S7: =IF(OR(Q7="",R7=""),"",Q7*IF(R7="Monthly",12,IF(R7="Quarterly",4,IF(R7="Half-Yearly",2,IF(R7="Annual",1,IF(R7="One-time",0,1)))))) | AE7: =IF(U7="","",U7-TODAY()) | AF7: =IF(U7="","",IF(AD7<>"Active","Inactive",IF(AE7<0,"Expired",IF(AE7<=30,"Due within 30 days",IF(AE7<=60,"Due in 31-60 days",IF(AE7<=90,"Due in 61-90 days","Later"))))))
M8: =IF(OR(K8="",K8=0,L8=""),"",L8/K8) | Q8: =IF(OR(O8="",P8=""),"",O8*P8) | S8: =IF(OR(Q8="",R8=""),"",Q8*IF(R8="Monthly",12,IF(R8="Quarterly",4,IF(R8="Half-Yearly",2,IF(R8="Annual",1,IF(R8="One-time",0,1)))))) | AE8: =IF(U8="","",U8-TODAY()) | AF8: =IF(U8="","",IF(AD8<>"Active","Inactive",IF(AE8<0,"Expired",IF(AE8<=30,"Due within 30 days",IF(AE8<=60,"Due in 31-60 days",IF(AE8<=90,"Due in 61-90 days","Later"))))))
M9: =IF(OR(K9="",K9=0,L9=""),"",L9/K9) | Q9: =IF(OR(O9="",P9=""),"",O9*P9) | S9: =IF(OR(Q9="",R9=""),"",Q9*IF(R9="Monthly",12,IF(R9="Quarterly",4,IF(R9="Half-Yearly",2,IF(R9="Annual",1,IF(R9="One-time",0,1)))))) | AE9: =IF(U9="","",U9-TODAY()) | AF9: =IF(U9="","",IF(AD9<>"Active","Inactive",IF(AE9<0,"Expired",IF(AE9<=30,"Due within 30 days",IF(AE9<=60,"Due in 31-60 days",IF(AE9<=90,"Due in 61-90 days","Later"))))))
M10: =IF(OR(K10="",K10=0,L10=""),"",L10/K10) | Q10: =IF(OR(O10="",P10=""),"",O10*P10) | S10: =IF(OR(Q10="",R10=""),"",Q10*IF(R10="Monthly",12,IF(R10="Quarterly",4,IF(R10="Half-Yearly",2,IF(R10="Annual",1,IF(R10="One-time",0,1)))))) | AE10: =IF(U10="","",U10-TODAY()) | AF10: =IF(U10="","",IF(AD10<>"Active","Inactive",IF(AE10<0,"Expired",IF(AE10<=30,"Due within 30 days",IF(AE10<=60,"Due in 31-60 days",IF(AE10<=90,"Due in 61-90 days","Later"))))))
M11: =IF(OR(K11="",K11=0,L11=""),"",L11/K11) | Q11: =IF(OR(O11="",P11=""),"",O11*P11) | S11: =IF(OR(Q11="",R11=""),"",Q11*IF(R11="Monthly",12,IF(R11="Quarterly",4,IF(R11="Half-Yearly",2,IF(R11="Annual",1,IF(R11="One-time",0,1)))))) | AE11: =IF(U11="","",U11-TODAY()) | AF11: =IF(U11="","",IF(AD11<>"Active","Inactive",IF(AE11<0,"Expired",IF(AE11<=30,"Due within 30 days",IF(AE11<=60,"Due in 31-60 days",IF(AE11<=90,"Due in 61-90 days","Later"))))))
M12: =IF(OR(K12="",K12=0,L12=""),"",L12/K12) | Q12: =IF(OR(O12="",P12=""),"",O12*P12) | S12: =IF(OR(Q12="",R12=""),"",Q12*IF(R12="Monthly",12,IF(R12="Quarterly",4,IF(R12="Half-Yearly",2,IF(R12="Annual",1,IF(R12="One-time",0,1)))))) | AE12: =IF(U12="","",U12-TODAY()) | AF12: =IF(U12="","",IF(AD12<>"Active","Inactive",IF(AE12<0,"Expired",IF(AE12<=30,"Due within 30 days",IF(AE12<=60,"Due in 31-60 days",IF(AE12<=90,"Due in 61-90 days","Later"))))))
M13: =IF(OR(K13="",K13=0,L13=""),"",L13/K13) | Q13: =IF(OR(O13="",P13=""),"",O13*P13) | S13: =IF(OR(Q13="",R13=""),"",Q13*IF(R13="Monthly",12,IF(R13="Quarterly",4,IF(R13="Half-Yearly",2,IF(R13="Annual",1,IF(R13="One-time",0,1)))))) | AE13: =IF(U13="","",U13-TODAY()) | AF13: =IF(U13="","",IF(AD13<>"Active","Inactive",IF(AE13<0,"Expired",IF(AE13<=30,"Due within 30 days",IF(AE13<=60,"Due in 31-60 days",IF(AE13<=90,"Due in 61-90 days","Later"))))))
M14: =IF(OR(K14="",K14=0,L14=""),"",L14/K14) | Q14: =IF(OR(O14="",P14=""),"",O14*P14) | S14: =IF(OR(Q14="",R14=""),"",Q14*IF(R14="Monthly",12,IF(R14="Quarterly",4,IF(R14="Half-Yearly",2,IF(R14="Annual",1,IF(R14="One-time",0,1)))))) | AE14: =IF(U14="","",U14-TODAY()) | AF14: =IF(U14="","",IF(AD14<>"Active","Inactive",IF(AE14<0,"Expired",IF(AE14<=30,"Due within 30 days",IF(AE14<=60,"Due in 31-60 days",IF(AE14<=90,"Due in 61-90 days","Later"))))))
M15: =IF(OR(K15="",K15=0,L15=""),"",L15/K15) | Q15: =IF(OR(O15="",P15=""),"",O15*P15) | S15: =IF(OR(Q15="",R15=""),"",Q15*IF(R15="Monthly",12,IF(R15="Quarterly",4,IF(R15="Half-Yearly",2,IF(R15="Annual",1,IF(R15="One-time",0,1)))))) | AE15: =IF(U15="","",U15-TODAY()) | AF15: =IF(U15="","",IF(AD15<>"Active","Inactive",IF(AE15<0,"Expired",IF(AE15<=30,"Due within 30 days",IF(AE15<=60,"Due in 31-60 days",IF(AE15<=90,"Due in 61-90 days","Later"))))))
M16: =IF(OR(K16="",K16=0,L16=""),"",L16/K16) | Q16: =IF(OR(O16="",P16=""),"",O16*P16) | S16: =IF(OR(Q16="",R16=""),"",Q16*IF(R16="Monthly",12,IF(R16="Quarterly",4,IF(R16="Half-Yearly",2,IF(R16="Annual",1,IF(R16="One-time",0,1)))))) | AE16: =IF(U16="","",U16-TODAY()) | AF16: =IF(U16="","",IF(AD16<>"Active","Inactive",IF(AE16<0,"Expired",IF(AE16<=30,"Due within 30 days",IF(AE16<=60,"Due in 31-60 days",IF(AE16<=90,"Due in 61-90 days","Later"))))))
M17: =IF(OR(K17="",K17=0,L17=""),"",L17/K17) | Q17: =IF(OR(O17="",P17=""),"",O17*P17) | S17: =IF(OR(Q17="",R17=""),"",Q17*IF(R17="Monthly",12,IF(R17="Quarterly",4,IF(R17="Half-Yearly",2,IF(R17="Annual",1,IF(R17="One-time",0,1)))))) | AE17: =IF(U17="","",U17-TODAY()) | AF17: =IF(U17="","",IF(AD17<>"Active","Inactive",IF(AE17<0,"Expired",IF(AE17<=30,"Due within 30 days",IF(AE17<=60,"Due in 31-60 days",IF(AE17<=90,"Due in 61-90 days","Later"))))))
M18: =IF(OR(K18="",K18=0,L18=""),"",L18/K18) | Q18: =IF(OR(O18="",P18=""),"",O18*P18) | S18: =IF(OR(Q18="",R18=""),"",Q18*IF(R18="Monthly",12,IF(R18="Quarterly",4,IF(R18="Half-Yearly",2,IF(R18="Annual",1,IF(R18="One-time",0,1)))))) | AE18: =IF(U18="","",U18-TODAY()) | AF18: =IF(U18="","",IF(AD18<>"Active","Inactive",IF(AE18<0,"Expired",IF(AE18<=30,"Due within 30 days",IF(AE18<=60,"Due in 31-60 days",IF(AE18<=90,"Due in 61-90 days","Later"))))))
... M206: =IF(OR(K206="",K206=0,L206=""),"",L206/K206) | Q206: =IF(OR(O206="",P206=""),"",O206*P206) | S206: =IF(OR(Q206="",R206=""),"",Q206*IF(R206="Monthly",12,IF(R206="Quarterly",4,IF(R206="Half-Yearly",2,IF(R206="Annual",1,IF(R206="One-time",0,1)))))) | AE206: =IF(U206="","",U206-TODAY()) | AF206: =IF(U206="","",IF(AD206<>"Active","Inactive",IF(AE206<0,"Expired",IF(AE206<=30,"Due within 30 days",IF(AE206<=60,"Due in 31-60 days",IF(AE206<=90,"Due in 61-90 days","Later"))))))

Sheet IT Spend Log
A2: IT Spend Log
A3: Update the blue input cells. Formula-driven fields and dashboard results update automatically.
A6: Expense Date | B6: Reporting Month | C6: Expense ID | D6: Vendor | E6: Tool / Software | F6: Subscription Type | G6: Cost Category | H6: Department | I6: Invoice No. | J6: PO / Contract No. | K6: Base Amount (INR) | L6: GST (INR) | M6: Gross Amount (INR) | N6: TDS (INR) | O6: Net Paid / Payable (INR) | P6: Payment Date | Q6: Payment Status | R6: Payment Mode | S6: Budget Amount (INR) | T6: Variance to Budget (INR) | U6: Capex / Opex | V6: Cost Center | W6: Remarks
B7: =IF(A7="","",DATE(YEAR(A7),MONTH(A7),1)) | M7: =IF(K7="","",K7+IF(L7="",0,L7)) | O7: =IF(M7="","",M7-IF(N7="",0,N7)) | T7: =IF(OR(K7="",S7=""),"",K7-S7)
B8: =IF(A8="","",DATE(YEAR(A8),MONTH(A8),1)) | M8: =IF(K8="","",K8+IF(L8="",0,L8)) | O8: =IF(M8="","",M8-IF(N8="",0,N8)) | T8: =IF(OR(K8="",S8=""),"",K8-S8)
B9: =IF(A9="","",DATE(YEAR(A9),MONTH(A9),1)) | M9: =IF(K9="","",K9+IF(L9="",0,L9)) | O9: =IF(M9="","",M9-IF(N9="",0,N9)) | T9: =IF(OR(K9="",S9=""),"",K9-S9)
B10: =IF(A10="","",DATE(YEAR(A10),MONTH(A10),1)) | M10: =IF(K10="","",K10+IF(L10="",0,L10)) | O10: =IF(M10="","",M10-IF(N10="",0,N10)) | T10: =IF(OR(K10="",S10=""),"",K10-S10)
B11: =IF(A11="","",DATE(YEAR(A11),MONTH(A11),1)) | M11: =IF(K11="","",K11+IF(L11="",0,L11)) | O11: =IF(M11="","",M11-IF(N11="",0,N11)) | T11: =IF(OR(K11="",S11=""),"",K11-S11)
B12: =IF(A12="","",DATE(YEAR(A12),MONTH(A12),1)) | M12: =IF(K12="","",K12+IF(L12="",0,L12)) | O12: =IF(M12="","",M12-IF(N12="",0,N12)) | T12: =IF(OR(K12="",S12=""),"",K12-S12)
B13: =IF(A13="","",DATE(YEAR(A13),MONTH(A13),1)) | M13: =IF(K13="","",K13+IF(L13="",0,L13)) | O13: =IF(M13="","",M13-IF(N13="",0,N13)) | T13: =IF(OR(K13="",S13=""),"",K13-S13)
B14: =IF(A14="","",DATE(YEAR(A14),MONTH(A14),1)) | M14: =IF(K14="","",K14+IF(L14="",0,L14)) | O14: =IF(M14="","",M14-IF(N14="",0,N14)) | T14: =IF(OR(K14="",S14=""),"",K14-S14)
B15: =IF(A15="","",DATE(YEAR(A15),MONTH(A15),1)) | M15: =IF(K15="","",K15+IF(L15="",0,L15)) | O15: =IF(M15="","",M15-IF(N15="",0,N15)) | T15: =IF(OR(K15="",S15=""),"",K15-S15)
B16: =IF(A16="","",DATE(YEAR(A16),MONTH(A16),1)) | M16: =IF(K16="","",K16+IF(L16="",0,L16)) | O16: =IF(M16="","",M16-IF(N16="",0,N16)) | T16: =IF(OR(K16="",S16=""),"",K16-S16)
B17: =IF(A17="","",DATE(YEAR(A17),MONTH(A17),1)) | M17: =IF(K17="","",K17+IF(L17="",0,L17)) | O17: =IF(M17="","",M17-IF(N17="",0,N17)) | T17: =IF(OR(K17="",S17=""),"",K17-S17)
B18: =IF(A18="","",DATE(YEAR(A18),MONTH(A18),1)) | M18: =IF(K18="","",K18+IF(L18="",0,L18)) | O18: =IF(M18="","",M18-IF(N18="",0,N18)) | T18: =IF(OR(K18="",S18=""),"",K18-S18)
... B306: =IF(A306="","",DATE(YEAR(A306),MONTH(A306),1)) | M306: =IF(K306="","",K306+IF(L306="",0,L306)) | O306: =IF(M306="","",M306-IF(N306="",0,N306)) | T306: =IF(OR(K306="",S306=""),"",K306-S306)

Sheet Lists
A1: Status | B1: Category | C1: Department | D1: Frequency | E1: Yes No | F1: Criticality | G1: Deployment | H1: License Type | I1: Currency | J1: Subscription Type | K1: Payment Status | L1: Capex Opex | M1: Security Review | N1: Data Sensitivity | O1: Payment Mode
A2: Active | B2: ERP | C2: Accounts & Finance | D2: Monthly | E2: Yes | F2: Critical | G2: Cloud | H2: Named User | I2: INR | J2: AI | K2: Paid | L2: Opex | M2: Completed | N2: Public | O2: Corporate Card
A3: Inactive | B3: Finance & Accounting | C3: Retail | D3: Quarterly | E3: No | F3: High | G3: Desktop | H3: Concurrent | I3: USD | J3: SaaS | K3: Pending | L3: Capex | M3: Pending | N3: Internal | O3: Bank Transfer
A4: Under Review | B4: HRMS | C4: E-commerce | D4: Half-Yearly | F4: Medium | G4: On-premise | H4: Site License | I4: AED | J4: Cloud Hosting | K4: Part Paid | M4: Not Required | N4: Confidential | O4: UPI
A5: Planned | B5: POS | C5: Production | D5: Annual | F5: Low | G5: Hybrid | H5: Perpetual | I5: SAR | J5: Data / Analytics | K5: Not Due | N5: Restricted | O5: Auto Debit
A6: Expired | B6: Design | C6: Warehouse | D6: One-time | H6: Device | I6: EUR | J6: Communication | K6: Cancelled | O6: Other
B7: Security | C7: HR | H7: Enterprise | I7: GBP | J7: Domain / Website
B8: Productivity | C8: Marketing | H8: Other | J8: Marketing
B9: Cloud / Hosting | C9: Management | J9: Security
B10: Other | C10: IT | J10: Other
